[2020-11-29 02:35:02,782] {taskinstance.py:670} INFO - Dependencies all met for <TaskInstance: Write_data_to_PG.create_table 2020-11-28T21:00:00+00:00 [queued]>
[2020-11-29 02:35:02,799] {taskinstance.py:670} INFO - Dependencies all met for <TaskInstance: Write_data_to_PG.create_table 2020-11-28T21:00:00+00:00 [queued]>
[2020-11-29 02:35:02,800] {taskinstance.py:880} INFO - 
--------------------------------------------------------------------------------
[2020-11-29 02:35:02,800] {taskinstance.py:881} INFO - Starting attempt 1 of 1
[2020-11-29 02:35:02,800] {taskinstance.py:882} INFO - 
--------------------------------------------------------------------------------
[2020-11-29 02:35:02,814] {taskinstance.py:901} INFO - Executing <Task(PostgresOperator): create_table> on 2020-11-28T21:00:00+00:00
[2020-11-29 02:35:02,816] {standard_task_runner.py:54} INFO - Started process 67113 to run task
[2020-11-29 02:35:02,839] {standard_task_runner.py:77} INFO - Running: ['airflow', 'run', 'Write_data_to_PG', 'create_table', '2020-11-28T21:00:00+00:00', '--job_id', '580', '--pool', 'default_pool', '--raw', '-sd', 'DAGS_FOLDER/FileSensorDemo.py', '--cfg_path', '/var/folders/ff/pqhf5klx0msdsn3m1cnq4cxr0000gn/T/tmphmjk6qht']
[2020-11-29 02:35:02,841] {standard_task_runner.py:78} INFO - Job 580: Subtask create_table
[2020-11-29 02:35:02,888] {logging_mixin.py:112} INFO - Running %s on host %s <TaskInstance: Write_data_to_PG.create_table 2020-11-28T21:00:00+00:00 [running]> 47.43.168.192.in-addr.arpa
[2020-11-29 02:35:02,918] {postgres_operator.py:62} INFO - Executing: CREATE TABLE sampletable(
            Date text,
            Open text,
            High text,
            Low text,
            Close text
        );
        
[2020-11-29 02:35:02,927] {base_hook.py:89} INFO - Using connection to: id: postgres_default. Host: localhost, Port: None, Schema: testdb, Login: testuser, Password: XXXXXXXX, extra: None
[2020-11-29 02:35:02,933] {dbapi_hook.py:174} INFO - CREATE TABLE sampletable(
            Date text,
            Open text,
            High text,
            Low text,
            Close text
        );
        
[2020-11-29 02:35:02,935] {taskinstance.py:1150} ERROR - relation "sampletable" already exists
Traceback (most recent call last):
  File "/Users/yudi/opt/anaconda3/envs/airflow/lib/python3.6/site-packages/airflow/models/taskinstance.py", line 984, in _run_raw_task
    result = task_copy.execute(context=context)
  File "/Users/yudi/opt/anaconda3/envs/airflow/lib/python3.6/site-packages/airflow/operators/postgres_operator.py", line 65, in execute
    self.hook.run(self.sql, self.autocommit, parameters=self.parameters)
  File "/Users/yudi/opt/anaconda3/envs/airflow/lib/python3.6/site-packages/airflow/hooks/dbapi_hook.py", line 175, in run
    cur.execute(s)
psycopg2.errors.DuplicateTable: relation "sampletable" already exists

[2020-11-29 02:35:02,938] {taskinstance.py:1194} INFO - Marking task as FAILED. dag_id=Write_data_to_PG, task_id=create_table, execution_date=20201128T210000, start_date=20201128T210502, end_date=20201128T210502
[2020-11-29 02:35:07,779] {local_task_job.py:102} INFO - Task exited with return code 1
