[2020-11-30 05:40:48,310] {taskinstance.py:670} INFO - Dependencies all met for <TaskInstance: Write_data_to_PG.create_table 2020-11-30T00:05:00+00:00 [queued]>
[2020-11-30 05:40:48,477] {taskinstance.py:670} INFO - Dependencies all met for <TaskInstance: Write_data_to_PG.create_table 2020-11-30T00:05:00+00:00 [queued]>
[2020-11-30 05:40:48,478] {taskinstance.py:880} INFO - 
--------------------------------------------------------------------------------
[2020-11-30 05:40:48,479] {taskinstance.py:881} INFO - Starting attempt 1 of 1
[2020-11-30 05:40:48,479] {taskinstance.py:882} INFO - 
--------------------------------------------------------------------------------
[2020-11-30 05:40:48,599] {taskinstance.py:901} INFO - Executing <Task(PostgresOperator): create_table> on 2020-11-30T00:05:00+00:00
[2020-11-30 05:40:48,619] {standard_task_runner.py:54} INFO - Started process 89884 to run task
[2020-11-30 05:40:48,870] {standard_task_runner.py:77} INFO - Running: ['airflow', 'run', 'Write_data_to_PG', 'create_table', '2020-11-30T00:05:00+00:00', '--job_id', '840', '--pool', 'default_pool', '--raw', '-sd', 'DAGS_FOLDER/FileSensorDemo.py', '--cfg_path', '/var/folders/ff/pqhf5klx0msdsn3m1cnq4cxr0000gn/T/tmpuxv__9ev']
[2020-11-30 05:40:48,889] {standard_task_runner.py:78} INFO - Job 840: Subtask create_table
[2020-11-30 06:29:05,467] {logging_mixin.py:112} INFO - Running %s on host %s <TaskInstance: Write_data_to_PG.create_table 2020-11-30T00:05:00+00:00 [running]> 47.43.168.192.in-addr.arpa
[2020-11-30 06:29:05,512] {postgres_operator.py:62} INFO - Executing: CREATE TABLE sampletable(
            Date text,
            Open text,
            High text,
            Low text,
            Close text
        );
        
[2020-11-30 06:29:05,542] {base_hook.py:89} INFO - Using connection to: id: postgres_default. Host: localhost, Port: None, Schema: testdb, Login: testuser, Password: XXXXXXXX, extra: None
[2020-11-30 06:29:05,581] {dbapi_hook.py:174} INFO - CREATE TABLE sampletable(
            Date text,
            Open text,
            High text,
            Low text,
            Close text
        );
        
[2020-11-30 06:29:05,583] {taskinstance.py:1150} ERROR - relation "sampletable" already exists
Traceback (most recent call last):
  File "/Users/yudi/opt/anaconda3/envs/airflow/lib/python3.6/site-packages/airflow/models/taskinstance.py", line 984, in _run_raw_task
    result = task_copy.execute(context=context)
  File "/Users/yudi/opt/anaconda3/envs/airflow/lib/python3.6/site-packages/airflow/operators/postgres_operator.py", line 65, in execute
    self.hook.run(self.sql, self.autocommit, parameters=self.parameters)
  File "/Users/yudi/opt/anaconda3/envs/airflow/lib/python3.6/site-packages/airflow/hooks/dbapi_hook.py", line 175, in run
    cur.execute(s)
psycopg2.errors.DuplicateTable: relation "sampletable" already exists

[2020-11-30 06:29:05,588] {taskinstance.py:1194} INFO - Marking task as FAILED. dag_id=Write_data_to_PG, task_id=create_table, execution_date=20201130T000500, start_date=20201130T001048, end_date=20201130T005905
[2020-11-30 06:29:06,613] {local_task_job.py:102} INFO - Task exited with return code 1
