[2020-12-02 00:05:03,699] {taskinstance.py:670} INFO - Dependencies all met for <TaskInstance: Write_data_to_PG.create_table 2020-12-01T18:30:00+00:00 [queued]>
[2020-12-02 00:05:03,718] {taskinstance.py:670} INFO - Dependencies all met for <TaskInstance: Write_data_to_PG.create_table 2020-12-01T18:30:00+00:00 [queued]>
[2020-12-02 00:05:03,718] {taskinstance.py:880} INFO - 
--------------------------------------------------------------------------------
[2020-12-02 00:05:03,718] {taskinstance.py:881} INFO - Starting attempt 1 of 1
[2020-12-02 00:05:03,718] {taskinstance.py:882} INFO - 
--------------------------------------------------------------------------------
[2020-12-02 00:05:03,732] {taskinstance.py:901} INFO - Executing <Task(PostgresOperator): create_table> on 2020-12-01T18:30:00+00:00
[2020-12-02 00:05:03,734] {standard_task_runner.py:54} INFO - Started process 36874 to run task
[2020-12-02 00:05:03,766] {standard_task_runner.py:77} INFO - Running: ['airflow', 'run', 'Write_data_to_PG', 'create_table', '2020-12-01T18:30:00+00:00', '--job_id', '1178', '--pool', 'default_pool', '--raw', '-sd', 'DAGS_FOLDER/FileSensorDemo.py', '--cfg_path', '/var/folders/ff/pqhf5klx0msdsn3m1cnq4cxr0000gn/T/tmpovr3pwhk']
[2020-12-02 00:05:03,769] {standard_task_runner.py:78} INFO - Job 1178: Subtask create_table
[2020-12-02 00:05:03,818] {logging_mixin.py:112} INFO - Running %s on host %s <TaskInstance: Write_data_to_PG.create_table 2020-12-01T18:30:00+00:00 [running]> 47.43.168.192.in-addr.arpa
[2020-12-02 00:05:03,848] {postgres_operator.py:62} INFO - Executing: CREATE TABLE sampletable(
            Date text,
            Open text,
            High text,
            Low text,
            Close text
        );
        
[2020-12-02 00:05:03,859] {base_hook.py:89} INFO - Using connection to: id: postgres_default. Host: localhost, Port: None, Schema: testdb, Login: testuser, Password: XXXXXXXX, extra: None
[2020-12-02 00:05:03,863] {dbapi_hook.py:174} INFO - CREATE TABLE sampletable(
            Date text,
            Open text,
            High text,
            Low text,
            Close text
        );
        
[2020-12-02 00:05:03,865] {taskinstance.py:1150} ERROR - relation "sampletable" already exists
Traceback (most recent call last):
  File "/Users/yudi/opt/anaconda3/envs/airflow/lib/python3.6/site-packages/airflow/models/taskinstance.py", line 984, in _run_raw_task
    result = task_copy.execute(context=context)
  File "/Users/yudi/opt/anaconda3/envs/airflow/lib/python3.6/site-packages/airflow/operators/postgres_operator.py", line 65, in execute
    self.hook.run(self.sql, self.autocommit, parameters=self.parameters)
  File "/Users/yudi/opt/anaconda3/envs/airflow/lib/python3.6/site-packages/airflow/hooks/dbapi_hook.py", line 175, in run
    cur.execute(s)
psycopg2.errors.DuplicateTable: relation "sampletable" already exists

[2020-12-02 00:05:03,868] {taskinstance.py:1194} INFO - Marking task as FAILED. dag_id=Write_data_to_PG, task_id=create_table, execution_date=20201201T183000, start_date=20201201T183503, end_date=20201201T183503
[2020-12-02 00:05:08,694] {local_task_job.py:102} INFO - Task exited with return code 1
